Workbook

Sheet Sheet1
A1: ID | B1: Đời | C1: Đinh | D1: Họ và tên | E1: Năm sinh | F1: Năm mất | G1: Thông tin chi tiết | H1: Kỵ nhật | I1: Táng | J1: ID cha | K1: ID me | L1: ID chồng | M1: Khu vực | N1: Tọa X | O1: Tọa Y
A2: 10001 | B2: 1 | C2: x | D2: Dương Chính Mạnh | E2: ? | F2: ? | G2: Thủy tổ họ Dương, Quốc Oai | H2: ? | I2: Cửa Trại | M2: Trại
A3: 10001v1 | B3: 1 | D3: Cụ tổ bà đời 1 | L3: 10001
A4: 20001 | B4: 2 | C4: x | D4: Dương Chính Nghĩa | E4: ? | F4: ? | G4: Hiệu Phúc Hậu | H4: ? | I4: ? | J4: 10001 | M4: Trại
A5: 20001v1 | B5: 2 | D5: Cụ tổ bà đời 2 | L5: 20001
A6: 30001 | B6: 3 | C6: x | D6: Dương Đức Hậu | E6: ? | F6: ? | H6: ? | I6: ? | J6: 20001 | M6: Trại
A7: 30001v1 | B7: 3 | D7: Cụ tổ bà đời 3 | L7: 30001
A8: 40001 | B8: 4 | C8: x | D8: Dương Phúc Hiền | E8: ? | F8: ? | G8: Sinh 4 nam, 1 nữ | H8: ? | I8: ? | J8: 30001 | M8: Trại
A9: 40001v1 | B9: 4 | D9: Cụ tổ bà đời 4 | L9: 40001
A10: 50001 | B10: 5 | C10: x | D10: Dương Phúc Năng (N1) | E10: 1 | F10: ? | G10: Khởi tổ Ngành 1 | H10: 09/01 | J10: 40001 | M10: Cầu Cây Bàng
A11: 50001v1 | B11: 5 | D11: Cụ tổ bà đời 1 - Ngành 1 | L11: 50001
A12: 50002 | B12: 5 | C12: x | D12: Dương Phúc Thịnh (N2) | E12: 2 | F12: ? | G12: Khởi tổ Ngành 2 | H12: ? | I12: ? | J12: 40001 | M12: Khác
A13: 50002v1 | B13: 5 | D13: Cụ tổ bà đời 1 - Ngành 2 | L13: 50002
A14: 50003 | B14: 5 | C14: x | D14: Dương Vĩnh Trí (N3) | E14: 3 | F14: ? | G14: Khởi tổ Ngành 3 Hiệu Phúc Minh | H14: 16/01 | I14: ? | J14: 40001 | M14: Khác
A15: 50004 | B15: 5 | C15: x | D15: Dương Tảo Đạt | E15: 4 | F15: ? | G15: Tổ cậu | H15: 15/05 | I15: Đồng Cốc | J15: 40001 | M15: Vũng
A16: 40001g1 | B16: 5 | D16: Dương Thị Xuân Dung | E16: ? | F16: ? | G16: Cô tổ. Xuân Dung công chúa. Ông Chính thờ tự | H16: 11/11 | I16: Đồng Cốc | J16: 40001 | M16: Vũng
A17: 50003v1 | B17: 5 | D17: Đỗ Thị Từ Tại | G17: Hiệu Từ Tại | H17: 21/11 | L17: 50003 | M17: Khác
A18: 60005 | B18: 6 | C18: x | D18: Ngành 1 | J18: 50001 | M18: Khác
A19: 60006 | B19: 6 | C19: x | D19: Ngành 2 | J19: 50002 | M19: Khác
A20: 60001 | B20: 6 | C20: x | D20: Dương Tiến Tài | E20: 1 | F20: ? | G20: Tòng thượng | H20: ? | I20: ? | J20: 50003 | K20: 50003v1 | M20: Khác
A21: 60001v1 | B21: 6 | D21: Chưa rõ | L21: 60001
A22: 60002 | B22: 6 | C22: x | D22: Dương Pháp Cảnh | E22: 2 | F22: ? | H22: 18/10 | I22: ? | J22: 50003 | K22: 50003v1 | M22: Khác
A23: 60003 | B23: 6 | C23: x | D23: Dương Tiến Bàng | E23: 3 | F23: ? | G23: Hiệu Phúc Kiêm | H23: 04/12 | I23: ? | J23: 50003 | K23: 50003v1 | M23: Khác
A24: 60004 | B24: 6 | C24: x | D24: Dương Tiến Đạo | E24: 4 | F24: ? | I24: ? | J24: 50003 | K24: 50003v1 | M24: Khác
A25: 60004v1 | B25: 6 | D25: Chưa rõ | L25: 60004
A26: 60002v1 | B26: 6 | D26: Hiệu Từ Tuyên | E26: ? | F26: ? | G26: Hiệu Từ Tuyên | H26: 27/02 | I26: ? | L26: 60002 | M26: Khác
A27: 60003v1 | B27: 6 | D27: Nguyễn Thị Từ Tâm | E27: ? | F27: ? | G27: Hiệu Từ Tâm | H27: 08/12 | I27: ? | L27: 60003 | M27: Khác
A28: 70001 | B28: 7 | C28: x | D28: Dương Pháp Quý | E28: ? | F28: ? | H28: ? | I28: ? | J28: 60002 | K28: 60002v1 | M28: Khác
A29: 70002 | B29: 7 | C29: x | D29: Dương Tiến Hiền | E29: 1 | F29: ? | G29: Hiệu Phúc Tăng | H29: 27/10 | I29: Cầu Cây Bàng | J29: 60003 | K29: 60003v1 | M29: Cầu Cây Bàng
A30: 70003 | B30: 7 | C30: x | D30: Dương Tiến Thiện (P4N3) | E30: 2 | F30: ? | G30: Hiệu Phúc Dung | H30: 10/05 | I30: ? | J30: 60003 | K30: 60003v1 | M30: Khác
A31: 70001v1 | B31: 7 | D31: Nguyễn Thị Diệu Minh | E31: ? | F31: ? | G31: Hiệu Diệu Minh | H31: 18/03 | I31: ? | L31: 70001 | M31: Khác
A32: 70002v1 | B32: 7 | D32: Nguyễn Thị Quý | E32: ? | F32: ? | G32: Hiệu Từ Thuận | H32: ? | I32: ? | L32: 70002 | M32: Khác
A33: 70003v1 | B33: 7 | D33: Nguyễn Thị Từ Chất | E33: ? | F33: ? | I33: ? | L33: 70003 | M33: Khác
A34: 80002 | B34: 8 | C34: x | D34: Dương Huệ Phương (P1N3) | E34: ? | F34: ? | G34: Hiệu Hiền Lộc | H34: 08/01 | I34: ? | J34: 70001 | K34: 70001v1 | M34: Khác
A35: 80001 | B35: 8 | C35: x | D35: Dương Thuần Dụng | E35: 2 | F35: ? | G35: Hiệu Đôn Mẫn. Cụ tổ Phái 3 - Ngành 3 - Ông Chính thờ phụng | H35: 01/03 | I35: Bồ Cóc | J35: 70002 | K35: 70002v1 | M35: Bồ Cóc
A36: 80003 | B36: 8 | C36: x | D36: Dương Công Trạc (P2N3) | E36: 1 | F36: ? | G36: Hiệu Đông Thực | H36: 02/11 | I36: ? | J36: 70002 | K36: 70002v1 | M36: Khác
A37: 80004 | B37: 8 | C37: x | D37: Phái 4 ngành 3 (tiểu phái) | J37: 70003 | K37: 70003v1 | M37: Khác
A38: 80001v1 | B38: 8 | D38: Nguyễn Thị Trù | E38: ? | F38: ? | G38: Hiệu Từ Đức | H38: ? | I38: Cửa Trại | L38: 80001 | M38: Trại
A39: 80002v1 | B39: 8 | D39: Nguyễn Thị Từ Sơn | E39: ? | F39: ? | G39: Hiệu Từ Sơn | H39: 05/03 | I39: ? | L39: 80002 | M39: Khác
A40: 80003v1 | B40: 8 | D40: Nguyễn Thị Từ Ninh | E40: ? | F40: ? | G40: Hiệu Từ Ninh | H40: 08/12 | I40: ? | L40: 80003 | M40: Khác
...

Sheet Sheet3
A1: ID | B1: Đinh | C1: Đếm
A2: 10001 | B2: x | C2: =COUNTIF(Sheet1!L:L,Sheet3!A2) -> 1
A3: 20001 | B3: x | C3: =COUNTIF(Sheet1!L:L,Sheet3!A3) -> 1
A4: 30001 | B4: x | C4: =COUNTIF(Sheet1!L:L,Sheet3!A4) -> 1
A5: 40001 | B5: x | C5: =COUNTIF(Sheet1!L:L,Sheet3!A5) -> 1
A6: 50001 | B6: x | C6: =COUNTIF(Sheet1!L:L,Sheet3!A6) -> 1
A7: 50002 | B7: x | C7: =COUNTIF(Sheet1!L:L,Sheet3!A7) -> 1
A8: 50003 | B8: x | C8: =COUNTIF(Sheet1!L:L,Sheet3!A8) -> 1
A9: 50004 | B9: x | C9: =COUNTIF(Sheet1!L:L,Sheet3!A9) -> 0 | D9: Tổ cậu
A10: 60005 | B10: x | C10: =COUNTIF(Sheet1!L:L,Sheet3!A10) -> 0 | D10: Ngành 1
A11: 60006 | B11: x | C11: =COUNTIF(Sheet1!L:L,Sheet3!A11) -> 0 | D11: Ngành 2
A12: 60001 | B12: x | C12: =COUNTIF(Sheet1!L:L,Sheet3!A12) -> 1
A13: 60002 | B13: x | C13: =COUNTIF(Sheet1!L:L,Sheet3!A13) -> 1
A14: 60003 | B14: x | C14: =COUNTIF(Sheet1!L:L,Sheet3!A14) -> 1
A15: 60004 | B15: x | C15: =COUNTIF(Sheet1!L:L,Sheet3!A15) -> 1
A16: 70001 | B16: x | C16: =COUNTIF(Sheet1!L:L,Sheet3!A16) -> 1
A17: 70002 | B17: x | C17: =COUNTIF(Sheet1!L:L,Sheet3!A17) -> 1
A18: 70003 | B18: x | C18: =COUNTIF(Sheet1!L:L,Sheet3!A18) -> 1
A19: 80002 | B19: x | C19: =COUNTIF(Sheet1!L:L,Sheet3!A19) -> 1
A20: 80001 | B20: x | C20: =COUNTIF(Sheet1!L:L,Sheet3!A20) -> 1
A21: 80003 | B21: x | C21: =COUNTIF(Sheet1!L:L,Sheet3!A21) -> 1
A22: 80004 | B22: x | C22: =COUNTIF(Sheet1!L:L,Sheet3!A22) -> 0 | D22: Phái 4
A23: 90001 | B23: x | C23: =COUNTIF(Sheet1!L:L,Sheet3!A23) -> 1
A24: 90002 | B24: x | C24: =COUNTIF(Sheet1!L:L,Sheet3!A24) -> 0 | D24: Phái 1
A25: 90003 | B25: x | C25: =COUNTIF(Sheet1!L:L,Sheet3!A25) -> 0 | D25: Phái 2
A26: 100001 | B26: x | C26: =COUNTIF(Sheet1!L:L,Sheet3!A26) -> 1
A27: 100002 | B27: x | C27: =COUNTIF(Sheet1!L:L,Sheet3!A27) -> 2
A28: 100003 | B28: x | C28: =COUNTIF(Sheet1!L:L,Sheet3!A28) -> 1
A29: 110001 | B29: x | C29: =COUNTIF(Sheet1!L:L,Sheet3!A29) -> 2
A30: 110002 | B30: x | C30: =COUNTIF(Sheet1!L:L,Sheet3!A30) -> 1
A31: 110003 | B31: x | C31: =COUNTIF(Sheet1!L:L,Sheet3!A31) -> 1
A32: 110004 | B32: x | C32: =COUNTIF(Sheet1!L:L,Sheet3!A32) -> 1
A33: 110005 | B33: x | C33: =COUNTIF(Sheet1!L:L,Sheet3!A33) -> 1
A34: 110006 | B34: x | C34: =COUNTIF(Sheet1!L:L,Sheet3!A34) -> 2
A35: 110007 | B35: x | C35: =COUNTIF(Sheet1!L:L,Sheet3!A35) -> 1
A36: 110008 | B36: x | C36: =COUNTIF(Sheet1!L:L,Sheet3!A36) -> 2
A37: 120001 | B37: x | C37: =COUNTIF(Sheet1!L:L,Sheet3!A37) -> 2
... A47: 130005 | B47: x | C47: =COUNTIF(Sheet1!L:L,Sheet3!A47) -> 1
A48: 130006 | B48: x | C48: =COUNTIF(Sheet1!L:L,Sheet3!A48) -> 0 | D48: Tảo hóa
A49: 130007 | B49: x | C49: =COUNTIF(Sheet1!L:L,Sheet3!A49) -> 1
...
